<?xml version="1.0"?>

<robot xmlns:sensor="http://playerstage.sourceforge.net/gazebo/xmlschema/#sensor"
  xmlns:controller="http://playerstage.sourceforge.net/gazebo/xmlschema/#controller"
  xmlns:interface="http://playerstage.sourceforge.net/gazebo/xmlschema/#interface"
  xmlns:xacro="http://ros.org/wiki/xacro"
  >

  <!-- Chassis -->
  <link name="base_link">
    <inertial>
      <mass value="14.0"/>
      <origin xyz="0 0 0.177"/>
      <inertia ixx="0.14711667" ixy="0.0" ixz="0.0"
        iyy="0.334951167" iyz="0.0"
        izz="0.3978345"/>
    </inertial>
    <visual name="base_visual">
      <origin xyz="0 0 0.18" rpy="0 0 0"/>
        <geometry name="pioneer_geom">
            <mesh filename="package://p3at_description/meshes/p3at_meshes/chassis.dae"/>
        </geometry>
    </visual>
    <collision>
      <origin xyz="0 0 0.18" rpy="0 0 0"/>
      <geometry>
        <box size="0.501 0.3 0.19"/>
      </geometry>
    </collision>

    <!--
    <sensor name="gps" type="gps">
          <pose>0 0 0  0 0 0</pose>
          <update_rate>40.0</update_rate>
          <always_on>true</always_on>
          <gps>
            <position_sensing>
              <horizontal>
                <noise type="gaussian_quantized">
                  <mean>0</mean>
                  <stddev>1</stddev>
                  <bias_mean>3</bias_mean>
                  <bias_stddev>1</bias_stddev>
                  <precision>0.5</precision>
                </noise>
              </horizontal>
              <vertical>
                <noise type="gaussian_quantized">
                  <mean>0</mean>
                  <stddev>1</stddev>
                  <bias_mean>3</bias_mean>
                  <bias_stddev>1</bias_stddev>
                  <precision>1.0</precision>
                </noise>
              </vertical>
            </position_sensing>
            <velocity_sensing>
              <horizontal>
                <noise type="gaussian_quantized">
                  <mean>0</mean>
                  <stddev>0.1</stddev>
                  <bias_mean>0.1</bias_mean>
                  <bias_stddev>0.1</bias_stddev>
                  <precision>0.1</precision>
                </noise>
              </horizontal>
              <vertical>
                <noise type="gaussian_quantized">
                  <mean>0</mean>
                  <stddev>0.2</stddev>
                  <bias_mean>0.2</bias_mean>
                  <bias_stddev>0.2</bias_stddev>
                  <precision>0.2</precision>
                </noise>
              </vertical>
            </velocity_sensing>
          </gps>

        </sensor> -->
  </link>

  <link name="p3at_front_left_wheel">
    <inertial>
      <mass value="1.5"/>
      <origin xyz="0 0 0"/>
      <inertia ixx="0.005240625" ixy="0" ixz="0"
        iyy="0.005240625" iyz="0" izz="0.009075"/>
    </inertial>
    <visual name="visual">
      <origin xyz="0 0 0" rpy="0 0 0"/>
      <geometry name="geom">
        <mesh filename="package://p3at_description/meshes/p3at_meshes/wheel.dae"/>
      </geometry>
    </visual>
    <collision>
      <origin xyz="0 0 0" rpy="0 0 0"/>
      <geometry>
        <cylinder radius="0.110" length="0.075"/>
      </geometry>
    </collision>
  </link>

  <joint name="p3at_front_left_wheel_joint" type="continuous">
    <axis xyz="0 0 -1"/>
    <limit effort="100" velocity="100" />
    <joint_properties damping="0.7"/>
    <origin xyz="0.125 0.2010 0.11" rpy="1.5707 0 0"/>
    <parent link="base_link"/>
    <child link="p3at_front_left_wheel"/>
  </joint>

  <link name="p3at_front_right_wheel">
    <inertial>
      <mass value="1.5"/>
      <origin xyz="0 0 0"/>
      <inertia ixx="0.005240625" ixy="0" ixz="0"
        iyy="0.005240625" iyz="0" izz="0.009075"/>
    </inertial>
    <visual name="visual">
      <origin xyz="0 0 0" rpy="0 0 0"/>
      <geometry name="geom">
        <mesh filename="package://p3at_description/meshes/p3at_meshes/wheel.dae"/>
      </geometry>
    </visual>
    <collision>
      <origin xyz="0 0 0" rpy="0 0 0"/>
      <geometry>
        <cylinder radius="0.110" length="0.075"/>
      </geometry>
    </collision>
  </link>

  <joint name="p3at_front_right_wheel_joint" type="continuous">
    <axis xyz="0 0 -1"/>
    <limit effort="100" velocity="100" />
    <joint_properties damping="0.7"/>
    <origin xyz="0.125 -0.2010 0.11" rpy="1.5707 0 0"/>
    <parent link="base_link"/>
    <child link="p3at_front_right_wheel"/>
  </joint>



  <link name="p3at_rear_left_wheel">
    <inertial>
      <mass value="1.5"/>
      <origin xyz="0 0 0"/>
      <inertia ixx="0.005240625" ixy="0" ixz="0"
        iyy="0.005240625" iyz="0" izz="0.009075"/>
    </inertial>
    <visual name="visual">
      <origin xyz="0 0 0" rpy="0 0 0"/>
      <geometry name="geom">
        <mesh filename="package://p3at_description/meshes/p3at_meshes/wheel.dae"/>
      </geometry>
    </visual>
    <collision>
      <origin xyz="0 0 0" rpy="0 0 0"/>
      <geometry>
        <cylinder radius="0.110" length="0.075"/>
      </geometry>
    </collision>
  </link>

  <joint name="p3at_rear_left_wheel_joint" type="continuous">
    <axis xyz="0 0 -1"/>
    <limit effort="100" velocity="100" />
    <joint_properties damping="0.7"/>
    <origin xyz="-0.125 0.2010 0.11" rpy="1.5707 0 0"/>
    <parent link="base_link"/>
    <child link="p3at_rear_left_wheel"/>
  </joint>

  <link name="p3at_rear_right_wheel">
    <inertial>
      <mass value="1.5"/>
      <origin xyz="0 0 0"/>
      <inertia ixx="0.005240625" ixy="0" ixz="0"
        iyy="0.005240625" iyz="0" izz="0.009075"/>
    </inertial>
    <visual name="visual">
      <origin xyz="0 0 0" rpy="0 0 0"/>
      <geometry name="geom">
        <mesh filename="package://p3at_description/meshes/p3at_meshes/wheel.dae"/>
      </geometry>
    </visual>
    <collision>
      <origin xyz="0 0 0" rpy="0 0 0"/>
      <geometry>
        <cylinder radius="0.110" length="0.075"/>
      </geometry>
    </collision>
  </link>

  <joint name="p3at_rear_right_wheel_joint" type="continuous">
    <axis xyz="0 0 -1"/>
    <limit effort="100" velocity="100" />
    <joint_properties damping="0.7"/>
    <origin xyz="-0.125 -0.2010 0.11" rpy="1.5707 0 0"/>
    <parent link="base_link"/>
    <child link="p3at_rear_right_wheel"/>
  </joint>

  <!-- IMU sensor -->
  <!--<joint name="imu_joint" type="fixed">
   <axis xyz="1 0 0"/>
   <origin xyz="0 0 0.105"/>
   <parent link="base_link"/>
   <child link="imu_link"/>
 </joint>

 <link name="imu_link">
   <inertial>
     <mass value="0.001"/>
     <origin rpy="0 0 0" xyz="0 0 0"/>
     <inertia ixx="0.0001" ixy="0" ixz="0" iyy="0.000001" iyz="0" izz="0.0001"/>
   </inertial>
   <visual>
     <origin rpy="0 0 0" xyz="0 0 0"/>
     <geometry>
       <box size="0.01 0.01 0.01"/>
     </geometry>
     <material name="red"/>
   </visual>
   <collision>
     <origin rpy="0 0 0" xyz="0 0 0"/>
     <geometry>
       <box size=".01 .01 .01"/>
     </geometry>
   </collision>
 </link> -->

  <gazebo>
    <plugin name="skid_steer_drive_controller" filename="libgazebo_ros_skid_steer_drive.so">
      <updateRate>100.0</updateRate>
      <!--robotNamespace>$(arg robot_name)</robotNamespace-->
      <leftFrontJoint>p3at_front_left_wheel_joint</leftFrontJoint>
      <rightFrontJoint>p3at_front_right_wheel_joint</rightFrontJoint>
      <leftRearJoint>p3at_rear_left_wheel_joint</leftRearJoint>
      <rightRearJoint>p3at_rear_right_wheel_joint</rightRearJoint>
      <wheelSeparation>0.4</wheelSeparation>
      <wheelDiameter>0.215</wheelDiameter>
      <robotBaseFrame>base_link</robotBaseFrame>
      <torque>200</torque>
      <commandTopic>cmd_vel</commandTopic>
      <odometryTopic>odom</odometryTopic>
      <odometryFrame>odom</odometryFrame>
      <broadcastTF>true</broadcastTF>
    </plugin>

    <!-- todo : set robot_name argument instead of "sos1" -->


    <plugin name="hector_imu" filename="libhector_gazebo_ros_imu.so">
      <robotNamespace>/sos1</robotNamespace>
      <updateRate>50.0</updateRate>
      <bodyName>base_link</bodyName>
      <topicName>imu/data</topicName>
      <frameId>sos1/base_link</frameId>
      
      <accelDrift>0.005 0.005 0.005</accelDrift>
      <accelGaussianNoise>0.005 0.005 0.005</accelGaussianNoise>
      <rateDrift>0.005 0.005 0.005 </rateDrift>
      <rateGaussianNoise>0.005 0.005 0.005 </rateGaussianNoise>
      <headingDrift>0.005</headingDrift>
      <headingGaussianNoise>0.005</headingGaussianNoise>
    </plugin>

    <plugin name="hector_gps" filename="libhector_gazebo_ros_gps.so">
      <updateRate>40.0</updateRate>
      <bodyName>base_link</bodyName>
      <frameId>base_link</frameId>
      <topicName>fix</topicName>
      <velocityTopicName>fix_velocity</velocityTopicName>
      <referenceLatitude>49.860246</referenceLatitude>
      <referenceLongitude>8.687077</referenceLongitude>
      <drift>5.0 5.0 5.0</drift>
      <velocityDrift>0 0 0</velocityDrift>
      <gaussianNoise>0.01 0.01 0.01</gaussianNoise>
      <velocityGaussianNoise>0.05 0.05 0.05</velocityGaussianNoise>
    </plugin>

  </gazebo>



</robot>
